Workbook

Sheet Respostas
B1: Exercício 1 – Previsão de demanda por média móvel ponderada
B2: ABC Corporation – histórico de 60 meses de vendas (mil R$)
B4: Enunciado
B5: Considere o histórico de vendas dos últimos 60 meses da ABC Corporation, apresentado na aba "Média móvel ponderada". Faça a previsão de demanda para os próximos 12 meses usando o modelo de média móvel ponderada. Trabalhe com dois tamanhos de médias, justificando essas escolhas. A seguir, estime a acurácia das previsões por meio do Desvio Absoluto Médio (MAD) e use esses dados para definir os melhores pesos para cada previsão. Atente-se para a quantidade de observações para o cálculo do desvio médio.
B10: 1. Tamanhos de média escolhidos e justificativa
B11: Média móvel de 4 meses (n = 4) e média móvel de 12 meses (n = 12).
B12: • n = 4 (trimestral): janela curta, reage rapidamente a mudanças de nível e acompanha a tendência de crescimento da série (média dos meses 1–30 = 525,0 e dos meses 31–60 = 676,0 mil R$). Em compensação, filtra pouco a variação aleatória.
B14: • n = 12 (anual): janela longa, cobre um ciclo completo de 12 meses, elimina eventuais efeitos sazonais e suaviza fortemente o ruído (desvio-padrão da série = 109,3 mil R$). Em compensação, responde com atraso a mudanças de nível.
B16: • Os dois tamanhos representam, portanto, os extremos do trade-off "sensibilidade × estabilidade" citado em aula, o que torna a comparação entre eles informativa.
B19: 2. Pesos otimizados (definidos pela minimização do MAD)
B20: Os pesos foram obtidos por otimização (Solver – célula-objetivo: MAD; células variáveis: os pesos; restrições: soma dos pesos = 1 e todos os pesos ≥ 0). Estão gravados nas células amarelas da aba "Média móvel ponderada" (C31:C34 para n = 4 e D23:D34 para n = 12).
B23: Defasagem | C23: Peso – MM 4 | D23: Peso – MM 12
B24: t–12 (mais antigo) | C24: – | D24: ='Média móvel ponderada'!D23
B25: t–11 | C25: – | D25: ='Média móvel ponderada'!D24
B26: t–10 | C26: – | D26: ='Média móvel ponderada'!D25
B27: t–9 | C27: – | D27: ='Média móvel ponderada'!D26
B28: t–8 | C28: – | D28: ='Média móvel ponderada'!D27
B29: t–7 | C29: – | D29: ='Média móvel ponderada'!D28
B30: t–6 | C30: – | D30: ='Média móvel ponderada'!D29
B31: t–5 | C31: – | D31: ='Média móvel ponderada'!D30
B32: t–4 | C32: ='Média móvel ponderada'!C31 | D32: ='Média móvel ponderada'!D31
B33: t–3 | C33: ='Média móvel ponderada'!C32 | D33: ='Média móvel ponderada'!D32
B34: t–2 | C34: ='Média móvel ponderada'!C33 | D34: ='Média móvel ponderada'!D33
B35: t–1 (mais recente) | C35: ='Média móvel ponderada'!C34 | D35: ='Média móvel ponderada'!D34
B36: Soma | C36: ='Média móvel ponderada'!C35 | D36: ='Média móvel ponderada'!D35
B38: 3. Acurácia das previsões – Desvio Absoluto Médio (MAD)
B39: Atenção à quantidade de observações: a MM 4 já produz previsão a partir do mês 5, enquanto a MM 12 só produz a partir do mês 13. Comparar os MAD calculados sobre quantidades diferentes de observações levaria a uma conclusão errada; por isso a comparação decisiva é feita sobre a MESMA base (meses 13 a 60).
B42: Modelo | C42: Período avaliado | D42: Nº de previsões | E42: MAD (mil R$)
B43: Média móvel 4 | C43: Meses 5 a 60 | D43: =COUNT('Média móvel ponderada'!H41:H96) | E43: ='Média móvel ponderada'!H98
B44: Média móvel 4 | C44: Meses 13 a 60 | D44: =COUNT('Média móvel ponderada'!H49:H96) | E44: =AVERAGE('Média móvel ponderada'!H49:H96)
B45: Média móvel 12 | C45: Meses 13 a 60 | D45: =COUNT('Média móvel ponderada'!I49:I96) | E45: ='Média móvel ponderada'!I98
B47: As duas linhas destacadas em amarelo são as comparáveis entre si (mesmos 48 meses previstos).
B49: 4. Conclusão – qual média é mais acurada?
B50: Sobre a mesma base de 48 previsões (meses 13 a 60), a média móvel de 12 meses apresenta o menor MAD (≈ 65,5 mil R$) contra ≈ 69,2 mil R$ da média móvel de 4 meses — cerca de 5% mais acurada. Ou seja, apesar da tendência de crescimento, a série é dominada por variação aleatória de grande amplitude, e a janela mais longa filtra melhor esse ruído do que o ganho de sensibilidade obtido pela janela curta. Observe que o MAD da MM 4 calculado sobre TODAS as suas previsões (meses 5 a 60) é ≈ 63,0 mil R$ e, se fosse comparado diretamente com o da MM 12, sugeriria — incorretamente — que a MM 4 é melhor. A diferença vem apenas dos meses 5 a 12: naquele trecho inicial o nível de vendas era mais baixo e a série, mais estável (MAD da MM 4 nos meses 5 a 12 = 25,3 mil R$, contra 69,3 mil R$ nos meses 13 a 60). Daí a advertência do enunciado quanto ao número de observações. Recomendação: adotar a média móvel ponderada de 12 meses para a previsão dos meses 61 a 72.
B55: 5. Previsão de demanda para os próximos 12 meses (mil R$)
B56: Mês | C56: Média móvel 4 | D56: Média móvel 12
B57: 61 | C57: ='Média móvel ponderada'!C97 | D57: ='Média móvel ponderada'!D97
B58: 62 | C58: ='Média móvel ponderada'!C98 | D58: ='Média móvel ponderada'!D98
B59: 63 | C59: ='Média móvel ponderada'!C99 | D59: ='Média móvel ponderada'!D99
B60: 64 | C60: ='Média móvel ponderada'!C100 | D60: ='Média móvel ponderada'!D100
...

Sheet Média móvel ponderada
C11: PREVISÕES | H11: DESVIOS ABSOLUTOS
A13: Meses | B13: Total de vendas (mil R$) | C13: Média móvel 4 | D13: Média móvel 12 | H13: Média móvel 4 | I13: Média móvel 12
B15: Pesos | E15: PERÍODO MAIS ANTIGO
D23: 0
D24: 0
D25: 0.032190066
D26: 0
D27: 0
D28: 0.16932429
D29: 0.14298739
D30: 0.14574652
C31: 0.263007 | D31: 0.27816308
C32: 0.38418538 | D32: 0.19290997
C33: 0.11313159 | D33: 0
C34: 0.23967603 | D34: 0.038678687 | E34: PERÍODO MAIS RECENTE
B35: Soma dos pesos (= 1,00) | C35: =SUM(C15:C34) | D35: =SUM(D15:D34)
A37: 1 | B37: 458.03675
A38: 2 | B38: 444.69495
A39: 3 | B39: 581.62328
A40: 4 | B40: 588.35431
A41: 5 | B41: 517.65026 | C41: =SUMPRODUCT(B37:B40,$C$31:$C$34) | H41: =ABS(C41-B41)
A42: 6 | B42: 429.76345 | C42: =SUMPRODUCT(B38:B41,$C$31:$C$34) | H42: =ABS(C42-B42)
A43: 7 | B43: 540.57471 | C43: =SUMPRODUCT(B39:B42,$C$31:$C$34) | H43: =ABS(C43-B43)
A44: 8 | B44: 523.68651 | C44: =SUMPRODUCT(B40:B43,$C$31:$C$34) | H44: =ABS(C44-B44)
A45: 9 | B45: 483.7198 | C45: =SUMPRODUCT(B41:B44,$C$31:$C$34) | H45: =ABS(C45-B45)
A46: 10 | B46: 522.95684 | C46: =SUMPRODUCT(B42:B45,$C$31:$C$34) | H46: =ABS(C46-B46)
A47: 11 | B47: 537.01472 | C47: =SUMPRODUCT(B43:B46,$C$31:$C$34) | H47: =ABS(C47-B47)
A48: 12 | B48: 540.14436 | C48: =SUMPRODUCT(B44:B47,$C$31:$C$34) | H48: =ABS(C48-B48)
A49: 13 | B49: 328.88794 | C49: =SUMPRODUCT(B45:B48,$C$31:$C$34) | D49: =SUMPRODUCT(B37:B48,$D$23:$D$34) | H49: =ABS(C49-B49) | I49: =ABS(D49-B49)
A50: 14 | B50: 450.07079 | C50: =SUMPRODUCT(B46:B49,$C$31:$C$34) | D50: =SUMPRODUCT(B38:B49,$D$23:$D$34) | H50: =ABS(C50-B50) | I50: =ABS(D50-B50)
A51: 15 | B51: 557.04783 | C51: =SUMPRODUCT(B47:B50,$C$31:$C$34) | D51: =SUMPRODUCT(B39:B50,$D$23:$D$34) | H51: =ABS(C51-B51) | I51: =ABS(D51-B51)
A52: 16 | B52: 553.78665 | C52: =SUMPRODUCT(B48:B51,$C$31:$C$34) | D52: =SUMPRODUCT(B40:B51,$D$23:$D$34) | H52: =ABS(C52-B52) | I52: =ABS(D52-B52)
A53: 17 | B53: 487.51093 | C53: =SUMPRODUCT(B49:B52,$C$31:$C$34) | D53: =SUMPRODUCT(B41:B52,$D$23:$D$34) | H53: =ABS(C53-B53) | I53: =ABS(D53-B53)
A54: 18 | B54: 586.62986 | C54: =SUMPRODUCT(B50:B53,$C$31:$C$34) | D54: =SUMPRODUCT(B42:B53,$D$23:$D$34) | H54: =ABS(C54-B54) | I54: =ABS(D54-B54)
A55: 19 | B55: 504.12479 | C55: =SUMPRODUCT(B51:B54,$C$31:$C$34) | D55: =SUMPRODUCT(B43:B54,$D$23:$D$34) | H55: =ABS(C55-B55) | I55: =ABS(D55-B55)
A56: 20 | B56: 473.89968 | C56: =SUMPRODUCT(B52:B55,$C$31:$C$34) | D56: =SUMPRODUCT(B44:B55,$D$23:$D$34) | H56: =ABS(C56-B56) | I56: =ABS(D56-B56)
A57: 21 | B57: 668.59688 | C57: =SUMPRODUCT(B53:B56,$C$31:$C$34) | D57: =SUMPRODUCT(B45:B56,$D$23:$D$34) | H57: =ABS(C57-B57) | I57: =ABS(D57-B57)
A58: 22 | B58: 671.23801 | C58: =SUMPRODUCT(B54:B57,$C$31:$C$34) | D58: =SUMPRODUCT(B46:B57,$D$23:$D$34) | H58: =ABS(C58-B58) | I58: =ABS(D58-B58)
A59: 23 | B59: 535.08755 | C59: =SUMPRODUCT(B55:B58,$C$31:$C$34) | D59: =SUMPRODUCT(B47:B58,$D$23:$D$34) | H59: =ABS(C59-B59) | I59: =ABS(D59-B59)
A60: 24 | B60: 461.0088 | C60: =SUMPRODUCT(B56:B59,$C$31:$C$34) | D60: =SUMPRODUCT(B48:B59,$D$23:$D$34) | H60: =ABS(C60-B60) | I60: =ABS(D60-B60)
...
